Promise.resolve().then(() => {
    console.log('ok1')
    throw 'throw error1'
}).then(() => {
    console.log('ok2')
}, err => {     
    // 捕获错误
    console.log('err->', err)
}).then(() => {   
    // 该函数将被调用
    console.log('ok3')
    throw 'throw error3'
}).then(() => {
    // 错误捕获前的函数不会被调用
    console.log('ok4')
}).catch(err => {
    console.log('err->', err)
})
